2023-08-08 18:16:29,513 :: ERROR :: Internal Server Error: /categories/1/subscribe :: C:\Users\bkp20\PycharmProjects\NewsPortal\venv\Lib\site-packages\django\utils\log.py :: (<class 'Exception'>, Exception(), <traceback object at 0x00000242EE44B2C0>)
Traceback (most recent call last):
  File "C:\Users\bkp20\PycharmProjects\NewsPortal\venv\Lib\site-packages\django\core\handlers\exception.py", line 55, in inner
    response = get_response(request)
               ^^^^^^^^^^^^^^^^^^^^^
  File "C:\Users\bkp20\PycharmProjects\NewsPortal\venv\Lib\site-packages\django\core\handlers\base.py", line 197, in _get_response
    response = wrapped_callback(request, *callback_args, **callback_kwargs)
               ^^^^^^^^^^^^^^^^^^^^^^^^^^^^^^^^^^^^^^^^^^^^^^^^^^^^^^^^^^^^
  File "C:\Users\bkp20\PycharmProjects\NewsPortal\venv\Lib\site-packages\django\contrib\auth\decorators.py", line 23, in _wrapper_view
    return view_func(request, *args, **kwargs)
           ^^^^^^^^^^^^^^^^^^^^^^^^^^^^^^^^^^^
  File "C:\Users\bkp20\PycharmProjects\NewsPortal\venv\Lib\site-packages\django\utils\decorators.py", line 134, in _wrapper_view
    response = view_func(request, *args, **kwargs)
               ^^^^^^^^^^^^^^^^^^^^^^^^^^^^^^^^^^^
  File "C:\Users\bkp20\PycharmProjects\NewsPortal\NewsPaper\news\views.py", line 184, in subscribe
    raise Exception
Exception
2023-08-08 18:16:29,523 :: ERROR :: "GET /categories/1/subscribe HTTP/1.1" 500 83617 :: C:\Users\bkp20\PycharmProjects\NewsPortal\venv\Lib\site-packages\django\core\servers\basehttp.py :: None
2023-08-08 18:17:52,829 :: ERROR :: Internal Server Error: /categories/1/subscribe :: C:\Users\bkp20\PycharmProjects\NewsPortal\venv\Lib\site-packages\django\utils\log.py :: (<class 'Exception'>, Exception(), <traceback object at 0x000002893B321D80>)
Traceback (most recent call last):
  File "C:\Users\bkp20\PycharmProjects\NewsPortal\venv\Lib\site-packages\django\core\handlers\exception.py", line 55, in inner
    response = get_response(request)
               ^^^^^^^^^^^^^^^^^^^^^
  File "C:\Users\bkp20\PycharmProjects\NewsPortal\venv\Lib\site-packages\django\core\handlers\base.py", line 197, in _get_response
    response = wrapped_callback(request, *callback_args, **callback_kwargs)
               ^^^^^^^^^^^^^^^^^^^^^^^^^^^^^^^^^^^^^^^^^^^^^^^^^^^^^^^^^^^^
  File "C:\Users\bkp20\PycharmProjects\NewsPortal\venv\Lib\site-packages\django\contrib\auth\decorators.py", line 23, in _wrapper_view
    return view_func(request, *args, **kwargs)
           ^^^^^^^^^^^^^^^^^^^^^^^^^^^^^^^^^^^
  File "C:\Users\bkp20\PycharmProjects\NewsPortal\venv\Lib\site-packages\django\utils\decorators.py", line 134, in _wrapper_view
    response = view_func(request, *args, **kwargs)
               ^^^^^^^^^^^^^^^^^^^^^^^^^^^^^^^^^^^
  File "C:\Users\bkp20\PycharmProjects\NewsPortal\NewsPaper\news\views.py", line 184, in subscribe
    raise Exception
Exception
2023-08-08 18:17:54,653 :: ERROR :: "GET /categories/1/subscribe HTTP/1.1" 500 145 :: C:\Users\bkp20\PycharmProjects\NewsPortal\venv\Lib\site-packages\django\core\servers\basehttp.py :: None
2023-08-08 18:20:32,950 :: ERROR :: Internal Server Error: /categories/1/subscribe :: C:\Users\bkp20\PycharmProjects\NewsPortal\venv\Lib\site-packages\django\utils\log.py :: (<class 'Exception'>, Exception(), <traceback object at 0x000002893B4191C0>)
Traceback (most recent call last):
  File "C:\Users\bkp20\PycharmProjects\NewsPortal\venv\Lib\site-packages\django\core\handlers\exception.py", line 55, in inner
    response = get_response(request)
               ^^^^^^^^^^^^^^^^^^^^^
  File "C:\Users\bkp20\PycharmProjects\NewsPortal\venv\Lib\site-packages\django\core\handlers\base.py", line 197, in _get_response
    response = wrapped_callback(request, *callback_args, **callback_kwargs)
               ^^^^^^^^^^^^^^^^^^^^^^^^^^^^^^^^^^^^^^^^^^^^^^^^^^^^^^^^^^^^
  File "C:\Users\bkp20\PycharmProjects\NewsPortal\venv\Lib\site-packages\django\contrib\auth\decorators.py", line 23, in _wrapper_view
    return view_func(request, *args, **kwargs)
           ^^^^^^^^^^^^^^^^^^^^^^^^^^^^^^^^^^^
  File "C:\Users\bkp20\PycharmProjects\NewsPortal\venv\Lib\site-packages\django\utils\decorators.py", line 134, in _wrapper_view
    response = view_func(request, *args, **kwargs)
               ^^^^^^^^^^^^^^^^^^^^^^^^^^^^^^^^^^^
  File "C:\Users\bkp20\PycharmProjects\NewsPortal\NewsPaper\news\views.py", line 184, in subscribe
    raise Exception
Exception
2023-08-08 18:20:33,869 :: ERROR :: "GET /categories/1/subscribe HTTP/1.1" 500 145 :: C:\Users\bkp20\PycharmProjects\NewsPortal\venv\Lib\site-packages\django\core\servers\basehttp.py :: None
2023-08-08 18:30:51,181 :: ERROR :: Internal Server Error: /categories/3/subscribe :: C:\Users\bkp20\PycharmProjects\NewsPortal\venv\Lib\site-packages\django\utils\log.py :: (<class 'Exception'>, Exception(), <traceback object at 0x0000024236C73440>)
Traceback (most recent call last):
  File "C:\Users\bkp20\PycharmProjects\NewsPortal\venv\Lib\site-packages\django\core\handlers\exception.py", line 55, in inner
    response = get_response(request)
               ^^^^^^^^^^^^^^^^^^^^^
  File "C:\Users\bkp20\PycharmProjects\NewsPortal\venv\Lib\site-packages\django\core\handlers\base.py", line 197, in _get_response
    response = wrapped_callback(request, *callback_args, **callback_kwargs)
               ^^^^^^^^^^^^^^^^^^^^^^^^^^^^^^^^^^^^^^^^^^^^^^^^^^^^^^^^^^^^
  File "C:\Users\bkp20\PycharmProjects\NewsPortal\venv\Lib\site-packages\django\contrib\auth\decorators.py", line 23, in _wrapper_view
    return view_func(request, *args, **kwargs)
           ^^^^^^^^^^^^^^^^^^^^^^^^^^^^^^^^^^^
  File "C:\Users\bkp20\PycharmProjects\NewsPortal\venv\Lib\site-packages\django\utils\decorators.py", line 134, in _wrapper_view
    response = view_func(request, *args, **kwargs)
               ^^^^^^^^^^^^^^^^^^^^^^^^^^^^^^^^^^^
  File "C:\Users\bkp20\PycharmProjects\NewsPortal\NewsPaper\news\views.py", line 184, in subscribe
    raise Exception
Exception
2023-08-08 18:30:53,056 :: ERROR :: "GET /categories/3/subscribe HTTP/1.1" 500 145 :: C:\Users\bkp20\PycharmProjects\NewsPortal\venv\Lib\site-packages\django\core\servers\basehttp.py :: None
2023-08-08 19:25:46,213 :: ERROR :: Internal Server Error: /categories/2/subscribe :: C:\Users\bkp20\PycharmProjects\NewsPortal\venv\Lib\site-packages\django\utils\log.py :: (<class 'Exception'>, Exception(), <traceback object at 0x0000025A9669C1C0>)
Traceback (most recent call last):
  File "C:\Users\bkp20\PycharmProjects\NewsPortal\venv\Lib\site-packages\django\core\handlers\exception.py", line 55, in inner
    response = get_response(request)
               ^^^^^^^^^^^^^^^^^^^^^
  File "C:\Users\bkp20\PycharmProjects\NewsPortal\venv\Lib\site-packages\django\core\handlers\base.py", line 197, in _get_response
    response = wrapped_callback(request, *callback_args, **callback_kwargs)
               ^^^^^^^^^^^^^^^^^^^^^^^^^^^^^^^^^^^^^^^^^^^^^^^^^^^^^^^^^^^^
  File "C:\Users\bkp20\PycharmProjects\NewsPortal\venv\Lib\site-packages\django\contrib\auth\decorators.py", line 23, in _wrapper_view
    return view_func(request, *args, **kwargs)
           ^^^^^^^^^^^^^^^^^^^^^^^^^^^^^^^^^^^
  File "C:\Users\bkp20\PycharmProjects\NewsPortal\venv\Lib\site-packages\django\utils\decorators.py", line 134, in _wrapper_view
    response = view_func(request, *args, **kwargs)
               ^^^^^^^^^^^^^^^^^^^^^^^^^^^^^^^^^^^
  File "C:\Users\bkp20\PycharmProjects\NewsPortal\NewsPaper\news\views.py", line 184, in subscribe
    raise Exception
Exception
2023-08-08 19:25:46,222 :: ERROR :: "GET /categories/2/subscribe HTTP/1.1" 500 84438 :: C:\Users\bkp20\PycharmProjects\NewsPortal\venv\Lib\site-packages\django\core\servers\basehttp.py :: None
2023-08-08 19:26:22,614 :: ERROR :: Internal Server Error: /categories/2/subscribe :: C:\Users\bkp20\PycharmProjects\NewsPortal\venv\Lib\site-packages\django\utils\log.py :: (<class 'Exception'>, Exception(), <traceback object at 0x000001CF0288DD00>)
Traceback (most recent call last):
  File "C:\Users\bkp20\PycharmProjects\NewsPortal\venv\Lib\site-packages\django\core\handlers\exception.py", line 55, in inner
    response = get_response(request)
               ^^^^^^^^^^^^^^^^^^^^^
  File "C:\Users\bkp20\PycharmProjects\NewsPortal\venv\Lib\site-packages\django\core\handlers\base.py", line 197, in _get_response
    response = wrapped_callback(request, *callback_args, **callback_kwargs)
               ^^^^^^^^^^^^^^^^^^^^^^^^^^^^^^^^^^^^^^^^^^^^^^^^^^^^^^^^^^^^
  File "C:\Users\bkp20\PycharmProjects\NewsPortal\venv\Lib\site-packages\django\contrib\auth\decorators.py", line 23, in _wrapper_view
    return view_func(request, *args, **kwargs)
           ^^^^^^^^^^^^^^^^^^^^^^^^^^^^^^^^^^^
  File "C:\Users\bkp20\PycharmProjects\NewsPortal\venv\Lib\site-packages\django\utils\decorators.py", line 134, in _wrapper_view
    response = view_func(request, *args, **kwargs)
               ^^^^^^^^^^^^^^^^^^^^^^^^^^^^^^^^^^^
  File "C:\Users\bkp20\PycharmProjects\NewsPortal\NewsPaper\news\views.py", line 184, in subscribe
    raise Exception
Exception
2023-08-08 19:26:24,368 :: ERROR :: "GET /categories/2/subscribe HTTP/1.1" 500 145 :: C:\Users\bkp20\PycharmProjects\NewsPortal\venv\Lib\site-packages\django\core\servers\basehttp.py :: None
