2023-08-09 18:09:27,256 :: ERROR :: exception :: 
Traceback (most recent call last):
  File "C:\Users\bkp20\PycharmProjects\NewsPortal\venv\Lib\site-packages\django\core\handlers\exception.py", line 55, in inner
    response = get_response(request)
               ^^^^^^^^^^^^^^^^^^^^^
  File "C:\Users\bkp20\PycharmProjects\NewsPortal\venv\Lib\site-packages\django\core\handlers\base.py", line 197, in _get_response
    response = wrapped_callback(request, *callback_args, **callback_kwargs)
               ^^^^^^^^^^^^^^^^^^^^^^^^^^^^^^^^^^^^^^^^^^^^^^^^^^^^^^^^^^^^
  File "C:\Users\bkp20\PycharmProjects\NewsPortal\venv\Lib\site-packages\django\contrib\auth\decorators.py", line 23, in _wrapper_view
    return view_func(request, *args, **kwargs)
           ^^^^^^^^^^^^^^^^^^^^^^^^^^^^^^^^^^^
  File "C:\Users\bkp20\PycharmProjects\NewsPortal\venv\Lib\site-packages\django\utils\decorators.py", line 134, in _wrapper_view
    response = view_func(request, *args, **kwargs)
               ^^^^^^^^^^^^^^^^^^^^^^^^^^^^^^^^^^^
  File "C:\Users\bkp20\PycharmProjects\NewsPortal\NewsPaper\news\views.py", line 186, in subscribe
    raise SuspiciousOperation
django.core.exceptions.SuspiciousOperation
